Workbook

Sheet Bilgi
A1: GOPO — REV_C Malzeme Listesi (BOM)
A3: Kaynak | B3: hardware/*.kicad_sch (usb_c_input, usb_pd_controller, mcu, userinterface)
A4: Şema revizyonu | B4: rev_c dalı, commit 82ec479
A5: Alan standardı | B5: design_decisions/standards/komponent-field-standardi.csv
A6: Üretim tarihi | B6: 2026-09-18
A8: GRUPLAMA KURALI
A9: Anahtar | B9: Standardın GroupBy='Evet' alanları: Value, Footprint, Manufacturer, MPN, Package + komponentin grubuna özel alanlar
A10: Neden yalnız Value değil | B10: '22u' hem C5/C20/C21 kondansatörlerinin hem de L1 bobininin değeri; '2u2' hem C3 hem L2. Yalnız Value ile gruplamak bunları tek satıra koyardı. Aynı şekilde 10u/47u kondansatörler 0402 ve 1210 ayağında ayrı satır olmalıdır.
A11: Aynı değer, ayrı satır | B11: Aynı Value ve ayağa sahip parçalar parametreleri farklıysa ayrı satırdır. 3 yerde fark gerçektir (100k dirençler %0.1 ve %1 toleransta; 100n kondansatörler 16V ve 50V; 47u/1210 kondansatörler 10V ve 50V). 4 yerde ise bir taraf TBD olduğu için ayrılmıştır (10k, 10u/1210, 1u0, 22u/0402): TBD alanları doldurulunca bu satırlar birleşebilir. TBD bir parçayı spesifikasyonu belli olanla birleştirmek, ona sessizce o spesifikasyonu atamak olurdu; bu yüzden ayrı bırakıldı.
A13: SAYFALAR
A14: BOM | B14: Sipariş satırları. Adet ve Durum sütunları formüldür.
A15: Komponentler | B15: Referans başına düz liste; hangi referans hangi BOM satırında.
A16: Parametreler | B16: BOM satırı başına gruba özel elektriksel alanlar (uzun biçim).
A17: Eksikler | B17: Hangi alan kaç satırda TBD — satın alma öncesi kapatılacak liste.
A19: OKUMA NOTLARI
A20: TBD | B20: Değeri henüz belirlenmemiş alan. Sarı dolgulu hücreler doldurulacaktır. Şemada da TBD yazar; uydurma veri girilmedi.
A21: DNP | B21: Do Not Populate — dizilmeyecek parça. Adet sütununa dahildir, sipariş miktarına dahil DEĞİLDİR.
A22: Satın alınmayanlar | B22: TP1..TP13 test pedleri kart üzerinde açılan pedlerdir. J5/J6 panel montajlı jaklardır, kartta yalnız mekanik ayak vardır.
A24: ÇÖZÜLMESİ GEREKEN TUTARSIZLIKLAR
A25: SW3 | B25: BOM_PRELIMINARY_20260911 bu referans için L-KLS4-EC12-012424-W yazıyor; şema sembolü ve ayağı EC1121S-E5A-F12.5. Satın alma öncesi tek parçada birleştirilmeli.
A26: U10 | B26: Parça TPD4EUSB30 ama Datasheet bağlantısı TPD2EUSB30A gösteriyor.
A27: D3 / D7 | B27: Parça SMBJ30A ama Datasheet bağlantısı SMAJ serisini gösteriyor.
A28: J3 | B28: Value ekran modülünün adı (NHD-2.4-240320AF-CSXP); MPN ise kart üstündeki Molex 54132-4062 konnektörü. Ekran modülü ayrı sipariş kalemidir.
A29: R11 / RShunt1 | B29: İkisi de 5m0 şönt ama farklı netlerde: R11 VBUS ölçümü, RShunt1 INA228 çıkış ölçümü. Referans öneki RShunt1 standart dışıdır.
A30: SW1 / SW2 | B30: Aynı parça (C&K PTS810 SJS 250 SMTR LFS) ama Value alanları 'BOOT / PTS810' ve 'RESET / PTS810' olduğu için BOM'da İKİ SATIR. Standarda göre Value ürün adı olmalı, işlev DesignNote alanına yazılmalı (zaten yazılı). Value şemada PTS810 olarak düzeltilirse bu iki satır tek sipariş kalemine iner.

Sheet BOM
A1: # | B1: Adet | C1: Referanslar | D1: Value | E1: Açıklama | F1: Package | G1: Footprint | H1: Üretici | I1: MPN | J1: Kategori | K1: Alt Kategori | L1: Montaj | M1: Lifecycle | N1: RoHS | O1: DNP | P1: Sayfalar | Q1: Durum | R1: Datasheet | S1: Tasarım Notu
A2: 1 | B2: =IF(C2="",0,LEN(C2)-LEN(SUBSTITUTE(C2,",",""))+1) | C2: U5 | D2: AOZ1284PI | E2: 4A Buck Regulator, 3-36V input, 0.8-30V output, 0.2 - 2MHz, SOIC-8 | F2: SOIC-8-EP | G2: Package_SO:SOIC-8-1EP_3.9x4.9mm_P1.27mm_EP2.71x3.7mm | H2: Alpha & Omega Semiconductor | I2: AOZ1284PI | J2: Integrated Circuits | K2: PMIC - Voltage Regulators - DC DC Switching | L2: Surface Mount | M2: TBD | N2: TBD | P2: USB_PD_CONTROLLER | Q2: =IF(O2="EVET","DNP",IF(I2="N/A","SATIN ALINMAZ",IF(I2="TBD","MPN GEREKLİ","SEÇİLDİ"))) | R2: https://www.aosmd.com/res/datasheets/AOZ1284PI.pdf | S2: Tedarik: Ozdisan.
A3: 2 | B3: =IF(C3="",0,LEN(C3)-LEN(SUBSTITUTE(C3,",",""))+1) | C3: U1 | D3: AP33772SDKZ-13-FA02 | E3: USB Type-C PD3.1 Sink Controller, EPR/AVS up to 28V, SPR/AVS up to 21V, I2C interface, WQFN-24 | F3: WQFN-24 (4x4mm) | G3: Package_DFN_QFN:Texas_RTW_WQFN-24-1EP_4x4mm_P0.5mm_EP2.7x2.7mm | H3: Diodes Incorporated | I3: AP33772SDKZ-13-FA02 | J3: Integrated Circuits | K3: Interface - Specialized (USB PD) | L3: Surface Mount | M3: TBD | N3: TBD | P3: USB_PD_CONTROLLER | Q3: =IF(O3="EVET","DNP",IF(I3="N/A","SATIN ALINMAZ",IF(I3="TBD","MPN GEREKLİ","SEÇİLDİ"))) | R3: https://www.diodes.com/datasheet/download/AP33772S.pdf | S3: Kesin parca; kapi surusu Q3/Q4 ile dogrulanmali.
A4: 3 | B4: =IF(C4="",0,LEN(C4)-LEN(SUBSTITUTE(C4,",",""))+1) | C4: U12 | D4: AP74502Q | E4: TBD | F4: TSOT-23-8 | G4: Package_TO_SOT_SMD:TSOT-23-8_HandSoldering | H4: Power_Path_Custom | I4: AP74502Q | J4: Integrated Circuits | K4: PMIC - Power Distribution Switches, Load Drivers | L4: Surface Mount | M4: TBD | N4: TBD | P4: USB_PD_CONTROLLER | Q4: =IF(O4="EVET","DNP",IF(I4="N/A","SATIN ALINMAZ",IF(I4="TBD","MPN GEREKLİ","SEÇİLDİ"))) | R4: ~ | S4: TBD
A5: 4 | B5: =IF(C5="",0,LEN(C5)-LEN(SUBSTITUTE(C5,",",""))+1) | C5: U8 | D5: CAT4104V-GT3 | E5: Resistor | F5: SOIC-8 | G5: Package_SO:SOIC-8_3.9x4.9mm_P1.27mm | H5: onsemi | I5: CAT4104V-GT3 | J5: Integrated Circuits | K5: PMIC - LED Drivers | L5: Surface Mount | M5: TBD | N5: TBD | P5: USER INTERFACE | Q5: =IF(O5="EVET","DNP",IF(I5="N/A","SATIN ALINMAZ",IF(I5="TBD","MPN GEREKLİ","SEÇİLDİ"))) | R5: https://www.onsemi.com/download/data-sheet/pdf/cat4104-d.pdf | S5: TBD
A6: 5 | B6: =IF(C6="",0,LEN(C6)-LEN(SUBSTITUTE(C6,",",""))+1) | C6: U2 | D6: ESP32-C6-WROOM-1 | E6: ESP32-C6-WROOM-1/U is a module that supports 2.4 GHz Wi-Fi 6 (802.11 ax), Bluetooth® 5 (LE), Zigbee and Thread (802.15.4) | F6: WROOM-1 Module (18x25.5mm) | G6: PCM_Espressif:ESP32-C6-WROOM-1 | H6: Espressif Systems | I6: ESP32-C6-WROOM-1 | J6: Integrated Circuits | K6: Embedded - Microcontrollers / RF Modules | L6: Surface Mount | M6: TBD | N6: TBD | P6: MCU | Q6: =IF(O6="EVET","DNP",IF(I6="N/A","SATIN ALINMAZ",IF(I6="TBD","MPN GEREKLİ","SEÇİLDİ"))) | R6: https://www.espressif.com/sites/default/files/documentation/esp32-c6-wroom-1_wroom-1u_datasheet_en.pdf | S6: Modul varyanti / flash kapasitesi satin alma oncesi sabitlenmeli.
A7: 6 | B7: =IF(C7="",0,LEN(C7)-LEN(SUBSTITUTE(C7,",",""))+1) | C7: U3 | D7: INA228 | E7: High-Side or Low-Side Measurement, Bi-Directional Current and Power Monitor (0-85V) with I2C, SMBus-, and PMBus-Compatible Interface, TSSOP-10 (Texas DGS0010A / VSSOP) | F7: VSSOP-10 (DGS) | G7: Package_SO:TSSOP-10_3x3mm_P0.5mm | H7: Texas Instruments | I7: INA228AIDGSR | J7: Integrated Circuits | K7: Linear - Amplifiers / Data Acquisition | L7: Surface Mount | M7: TBD | N7: TBD | P7: USB_PD_CONTROLLER | Q7: =IF(O7="EVET","DNP",IF(I7="N/A","SATIN ALINMAZ",IF(I7="TBD","MPN GEREKLİ","SEÇİLDİ"))) | R7: https://www.ti.com/lit/ds/symlink/ina228.pdf | S7: Siparis suffix'i ve sicaklik sinifi secilmeli.
A8: 7 | B8: =IF(C8="",0,LEN(C8)-LEN(SUBSTITUTE(C8,",",""))+1) | C8: U4 | D8: RV-3028-C7 | E8: Realtime Clock/Calendar I2C Interface, Extreme Low Power, 1.1 V to 5.5 V, MicroCrystal C7 | F8: C7 SON-8 (1.5x3.2mm) | G8: Package_SON:MicroCrystal_C7_SON-8_1.5x3.2mm_P0.9mm | H8: Micro Crystal | I8: RV-3028-C7 | J8: Integrated Circuits | K8: Logic / Memory / Clock-Timing | L8: Surface Mount | M8: TBD | N8: TBD | P8: MCU | Q8: =IF(O8="EVET","DNP",IF(I8="N/A","SATIN ALINMAZ",IF(I8="TBD","MPN GEREKLİ","SEÇİLDİ"))) | R8: https://www.microcrystal.com/fileadmin/Media/Products/RTC/Datasheet/RV-3028-C7.pdf | S8: Trickle charge kapali kullanilacak.
A9: 8 | B9: =IF(C9="",0,LEN(C9)-LEN(SUBSTITUTE(C9,",",""))+1) | C9: U6 | D9: TL431BIDBZR | E9: TBD | F9: SOT-23 | G9: Package_TO_SOT_SMD:SOT-23 | H9: Texas Instruments | I9: TL431BIDBZR | J9: Integrated Circuits | K9: Linear - Amplifiers / Data Acquisition | L9: Surface Mount | M9: TBD | N9: TBD | P9: USB_PD_CONTROLLER | Q9: =IF(O9="EVET","DNP",IF(I9="N/A","SATIN ALINMAZ",IF(I9="TBD","MPN GEREKLİ","SEÇİLDİ"))) | R9: TBD | S9: TI TL431 DBZ: K=1, REF=2, A=3. REF, K'ya bagli. Ek kapasitif yuk yok.
A10: 9 | B10: =IF(C10="",0,LEN(C10)-LEN(SUBSTITUTE(C10,",",""))+1) | C10: U10 | D10: TPD4EUSB30 | E10: 4-Channel ESD Protection for Super-Speed USB 3.0 Interface, USON-10 | F10: USON-10 (2.5x1.0mm) | G10: Package_SON:USON-10_2.5x1.0mm_P0.5mm | H10: Texas Instruments | I10: TPD4EUSB30 | J10: Circuit Protection | K10: TVS Diodes | L10: Surface Mount | M10: TBD | N10: TBD | P10: USB_C_INPUT | Q10: =IF(O10="EVET","DNP",IF(I10="N/A","SATIN ALINMAZ",IF(I10="TBD","MPN GEREKLİ","SEÇİLDİ"))) | R10: http://www.ti.com/lit/ds/symlink/tpd2eusb30a.pdf | S10: USB2.0 veri hatti ESD dizisi.
A11: 10 | B11: =IF(C11="",0,LEN(C11)-LEN(SUBSTITUTE(C11,",",""))+1) | C11: U11 | D11: TPS55340PWPR | E11: TBD | F11: HTSSOP-14 (PWP) | G11: Package_SO:Texas_HTSSOP-14-1EP_4.4x5mm_P0.65mm_EP3.4x5mm_Mask3.155x3.255mm_ThermalVias | H11: Texas Instruments | I11: TPS55340PWPR | J11: Integrated Circuits | K11: PMIC - Voltage Regulators - DC DC Switching | L11: Surface Mount | M11: TBD | N11: TBD | P11: USB_PD_CONTROLLER | Q11: =IF(O11="EVET","DNP",IF(I11="N/A","SATIN ALINMAZ",IF(I11="TBD","MPN GEREKLİ","SEÇİLDİ"))) | R11: ~ | S11: TBD
A12: 11 | B12: =IF(C12="",0,LEN(C12)-LEN(SUBSTITUTE(C12,",",""))+1) | C12: U7 | D12: TPS61023DRLR | E12: Resistor | F12: TBD | G12: Power_Management_Custom:TPS61023_DRL0006A | H12: Texas Instruments | I12: TPS61023DRLR | J12: Integrated Circuits | K12: PMIC - Voltage Regulators - DC DC Switching | L12: Surface Mount | M12: TBD | N12: TBD | P12: USER INTERFACE | Q12: =IF(O12="EVET","DNP",IF(I12="N/A","SATIN ALINMAZ",IF(I12="TBD","MPN GEREKLİ","SEÇİLDİ"))) | R12: https://www.ti.com/lit/ds/symlink/tps61023.pdf | S12: TBD
A13: 12 | B13: =IF(C13="",0,LEN(C13)-LEN(SUBSTITUTE(C13,",",""))+1) | C13: Q5, Q6 | D13: 60V 4mR TBD | E13: TBD | F13: TBD | H13: TBD | I13: TBD | J13: Discrete Semiconductor Products | K13: FETs, MOSFETs - Single | L13: TBD | M13: TBD | N13: TBD | P13: USB_PD_CONTROLLER | Q13: =IF(O13="EVET","DNP",IF(I13="N/A","SATIN ALINMAZ",IF(I13="TBD","MPN GEREKLİ","SEÇİLDİ"))) | R13: ~ | S13: Parca secilmedi; 60V / 4mOhm hedefi ile aranacak.
A14: 13 | B14: =IF(C14="",0,LEN(C14)-LEN(SUBSTITUTE(C14,",",""))+1) | C14: Q1, Q2 | D14: BSS138 | E14: 50V Vds, 0.22A Id, N-Channel MOSFET, SOT-23 | F14: SOT-23 | G14: Package_TO_SOT_SMD:SOT-23 | H14: onsemi | I14: BSS138 | J14: Discrete Semiconductor Products | K14: FETs, MOSFETs - Single | L14: Surface Mount | M14: TBD | N14: TBD | P14: USB_PD_CONTROLLER | Q14: =IF(O14="EVET","DNP",IF(I14="N/A","SATIN ALINMAZ",IF(I14="TBD","MPN GEREKLİ","SEÇİLDİ"))) | R14: https://www.onsemi.com/pub/Collateral/BSS138-D.PDF | S14: TBD
A15: 14 | B15: =IF(C15="",0,LEN(C15)-LEN(SUBSTITUTE(C15,",",""))+1) | C15: Q3, Q4 | D15: IRF7855TRPBF | E15: N-MOSFET transistor, gate/source/drain | F15: SOIC-8 | G15: Package_SO:SOIC-8_3.9x4.9mm_P1.27mm | H15: Infineon Technologies | I15: IRF7855TRPBF | J15: Discrete Semiconductor Products | K15: FETs, MOSFETs - Single | L15: Surface Mount | M15: TBD | N15: TBD | P15: USB_PD_CONTROLLER | Q15: =IF(O15="EVET","DNP",IF(I15="N/A","SATIN ALINMAZ",IF(I15="TBD","MPN GEREKLİ","SEÇİLDİ"))) | R15: TBD | S15: Prototip secimi; AP33772S kapi seviyesiyle kayip/SOA acik.
A16: 15 | B16: =IF(C16="",0,LEN(C16)-LEN(SUBSTITUTE(C16,",",""))+1) | C16: D5 | D16: BAT54 | E16: TBD | F16: SOD-123 | G16: Diode_SMD:D_SOD-123 | H16: TBD | I16: BAT54 | J16: Discrete Semiconductor Products | K16: Diodes | L16: Surface Mount | M16: TBD | N16: TBD | P16: USB_PD_CONTROLLER | Q16: =IF(O16="EVET","DNP",IF(I16="N/A","SATIN ALINMAZ",IF(I16="TBD","MPN GEREKLİ","SEÇİLDİ"))) | R16: ~ | S16: TBD
A17: 16 | B17: =IF(C17="",0,LEN(C17)-LEN(SUBSTITUTE(C17,",",""))+1) | C17: D6 | D17: BZT52C12 | E17: TBD | F17: SOD-123 | G17: Diode_SMD:D_SOD-123 | H17: TBD | I17: BZT52C12 | J17: Discrete Semiconductor Products | K17: Diodes | L17: Surface Mount | M17: TBD | N17: TBD | P17: USB_PD_CONTROLLER | Q17: =IF(O17="EVET","DNP",IF(I17="N/A","SATIN ALINMAZ",IF(I17="TBD","MPN GEREKLİ","SEÇİLDİ"))) | R17: ~ | S17: TBD
A18: 17 | B18: =IF(C18="",0,LEN(C18)-LEN(SUBSTITUTE(C18,",",""))+1) | C18: D1 | D18: LED | E18: Light emitting diode | F18: 0402 (1005 Metric) | G18: LED_SMD:LED_0402_1005Metric | H18: TBD | I18: TBD | J18: Optoelectronics | K18: LED Indication - Discrete | L18: Surface Mount | M18: TBD | N18: TBD | P18: USB_PD_CONTROLLER | Q18: =IF(O18="EVET","DNP",IF(I18="N/A","SATIN ALINMAZ",IF(I18="TBD","MPN GEREKLİ","SEÇİLDİ"))) | R18: TBD | S18: TBD
A19: 18 | B19: =IF(C19="",0,LEN(C19)-LEN(SUBSTITUTE(C19,",",""))+1) | C19: D3, D7 | D19: SMBJ30A | E19: 400W unidirectional Transient Voltage Suppressor, 30.0Vr, SMA(DO-214AC) | TBD | F19: SMB (DO-214AA) | G19: Diode_SMD:D_SMB | H19: TBD | I19: SMBJ30A | J19: Circuit Protection | K19: TVS Diodes | L19: Surface Mount | M19: TBD | N19: TBD | P19: USB_C_INPUT, USB_PD_CONTROLLER | Q19: =IF(O19="EVET","DNP",IF(I19="N/A","SATIN ALINMAZ",IF(I19="TBD","MPN GEREKLİ","SEÇİLDİ"))) | R19: https://www.littelfuse.com/media?resourcetype=datasheets&itemid=75e32973-b177-4ee3-a0ff-cedaf1abdb93&filename=smaj-datasheet | ~ | S19: TBD
A20: 19 | B20: =IF(C20="",0,LEN(C20)-LEN(SUBSTITUTE(C20,",",""))+1) | C20: D2 | D20: SS2060FL | E20: TBD | F20: SOD-123F | G20: Diode_SMD:D_SOD-123F | H20: PANJIT | I20: SS2060FL_R1_00001 | J20: Discrete Semiconductor Products | K20: Diodes | L20: Surface Mount | M20: TBD | N20: TBD | P20: USB_PD_CONTROLLER | Q20: =IF(O20="EVET","DNP",IF(I20="N/A","SATIN ALINMAZ",IF(I20="TBD","MPN GEREKLİ","SEÇİLDİ"))) | R20: https://www.ozdisan.com/p/schottky-diyotlar-385/panjit-ss2060fl-r1-00001-574723 | S20: Katot LX, anot GND. Tedarik: Ozdisan.
A21: 20 | B21: =IF(C21="",0,LEN(C21)-LEN(SUBSTITUTE(C21,",",""))+1) | C21: D4 | D21: SS34 TBD | E21: TBD | F21: SMA (DO-214AC) | G21: Diode_SMD:D_SMA | H21: TBD | I21: TBD | J21: Discrete Semiconductor Products | K21: Diodes | L21: Surface Mount | M21: TBD | N21: TBD | P21: USB_PD_CONTROLLER | Q21: =IF(O21="EVET","DNP",IF(I21="N/A","SATIN ALINMAZ",IF(I21="TBD","MPN GEREKLİ","SEÇİLDİ"))) | R21: ~ | S21: SS34 hedefi; kesin MPN secilmedi.
A22: 21 | B22: =IF(C22="",0,LEN(C22)-LEN(SUBSTITUTE(C22,",",""))+1) | C22: L1 | D22: 22u | E22: TBD | F22: 7.3x7.3x4.5mm | G22: Inductor_SMD:L_7.3x7.3_H4.5 | H22: CORE MASTER | I22: SRI0704-220M | J22: Inductors, Coils, Chokes | K22: Fixed Inductors | L22: Surface Mount | M22: TBD | N22: TBD | P22: USB_PD_CONTROLLER | Q22: =IF(O22="EVET","DNP",IF(I22="N/A","SATIN ALINMAZ",IF(I22="TBD","MPN GEREKLİ","SEÇİLDİ"))) | R22: https://store.comet.bg/download-file.php?id=16477 | S22: 22uH, 1.95A, 0.11ohm max; 1.95A'de 18.2uH (L -17%).
A23: 22 | B23: =IF(C23="",0,LEN(C23)-LEN(SUBSTITUTE(C23,",",""))+1) | C23: L2 | D23: 2u2 | E23: TBD | F23: MAPI-4030 (4.0x3.0mm) | G23: Inductor_SMD:L_Wuerth_MAPI-4030 | H23: Wurth Elektronik | I23: 74438357022 | J23: Inductors, Coils, Chokes | K23: Fixed Inductors | L23: Surface Mount | M23: TBD | N23: TBD | P23: USER INTERFACE | Q23: =IF(O23="EVET","DNP",IF(I23="N/A","SATIN ALINMAZ",IF(I23="TBD","MPN GEREKLİ","SEÇİLDİ"))) | R23: https://www.we-online.com/components/products/datasheet/74438357022.pdf | S23: Isat >=2A ve Irms >=1.5A (max sicaklikta) gerekir; ariza akimi kontrol edildi.
A24: 23 | B24: =IF(C24="",0,LEN(C24)-LEN(SUBSTITUTE(C24,",",""))+1) | C24: L3 | D24: 6u8 | E24: TBD | F24: 1210 (3225 Metric) | G24: Inductor_SMD:L_1210_3225Metric | H24: TBD | I24: TBD | J24: Inductors, Coils, Chokes | K24: Fixed Inductors | L24: Surface Mount | M24: TBD | N24: TBD | P24: USB_PD_CONTROLLER | Q24: =IF(O24="EVET","DNP",IF(I24="N/A","SATIN ALINMAZ",IF(I24="TBD","MPN GEREKLİ","SEÇİLDİ"))) | R24: ~ | S24: TBD
A25: 24 | B25: =IF(C25="",0,LEN(C25)-LEN(SUBSTITUTE(C25,",",""))+1) | C25: C14 | D25: 100n | E25: TBD | F25: 0402 (1005 Metric) | G25: Capacitor_SMD:C_0402_1005Metric | H25: TBD | I25: TBD | J25: Capacitors | K25: Ceramic Capacitors | L25: Surface Mount | M25: TBD | N25: TBD | P25: USB_PD_CONTROLLER | Q25: =IF(O25="EVET","DNP",IF(I25="N/A","SATIN ALINMAZ",IF(I25="TBD","MPN GEREKLİ","SEÇİLDİ"))) | R25: TBD | S25: X7R.
... A47: 46 | B47: =IF(C47="",0,LEN(C47)-LEN(SUBSTITUTE(C47,",",""))+1) | C47: R38 | D47: 100k | E47: TBD | F47: 0402 (1005 Metric) | G47: Resistor_SMD:R_0402_1005Metric | H47: TBD | I47: TBD | J47: Resistors | K47: Chip Resistor - Surface Mount | L47: Surface Mount | M47: TBD | N47: TBD | P47: USB_PD_CONTROLLER | Q47: =IF(O47="EVET","DNP",IF(I47="N/A","SATIN ALINMAZ",IF(I47="TBD","MPN GEREKLİ","SEÇİLDİ"))) | R47: TBD | S47: TBD
A48: 47 | B48: =IF(C48="",0,LEN(C48)-LEN(SUBSTITUTE(C48,",",""))+1) | C48: R21 | D48: 100k | E48: Resistor | F48: 0402 (1005 Metric) | G48: Resistor_SMD:R_0402_1005Metric | H48: TBD | I48: TBD | J48: Resistors | K48: Chip Resistor - Surface Mount | L48: Surface Mount | M48: TBD | N48: TBD | O48: EVET | P48: USB_PD_CONTROLLER | Q48: =IF(O48="EVET","DNP",IF(I48="N/A","SATIN ALINMAZ",IF(I48="TBD","MPN GEREKLİ","SEÇİLDİ"))) | R48: TBD | S48: TBD
A49: 48 | B49: =IF(C49="",0,LEN(C49)-LEN(SUBSTITUTE(C49,",",""))+1) | C49: R29, R42, R53, R58 | D49: 100k | E49: Resistor | TBD | F49: 0402 (1005 Metric) | G49: Resistor_SMD:R_0402_1005Metric | H49: TBD | I49: TBD | J49: Resistors | K49: Chip Resistor - Surface Mount | L49: Surface Mount | M49: TBD | N49: TBD | P49: USB_PD_CONTROLLER, USER INTERFACE | Q49: =IF(O49="EVET","DNP",IF(I49="N/A","SATIN ALINMAZ",IF(I49="TBD","MPN GEREKLİ","SEÇİLDİ"))) | R49: TBD | ~ | S49: TBD
A50: 49 | B50: =IF(C50="",0,LEN(C50)-LEN(SUBSTITUTE(C50,",",""))+1) | C50: R45 | D50: 100k | E50: Resistor | F50: 0402 (1005 Metric) | G50: Resistor_SMD:R_0402_1005Metric | H50: TBD | I50: TBD | J50: Resistors | K50: Chip Resistor - Surface Mount | L50: Surface Mount | M50: TBD | N50: TBD | P50: USER INTERFACE | Q50: =IF(O50="EVET","DNP",IF(I50="N/A","SATIN ALINMAZ",IF(I50="TBD","MPN GEREKLİ","SEÇİLDİ"))) | R50: TBD | S50: TBD
A51: 50 | B51: =IF(C51="",0,LEN(C51)-LEN(SUBSTITUTE(C51,",",""))+1) | C51: R39 | D51: 10k | E51: TBD | F51: 0402 (1005 Metric) | G51: Resistor_SMD:R_0402_1005Metric | H51: TBD | I51: TBD | J51: Resistors | K51: Chip Resistor - Surface Mount | L51: Surface Mount | M51: TBD | N51: TBD | P51: USB_PD_CONTROLLER | Q51: =IF(O51="EVET","DNP",IF(I51="N/A","SATIN ALINMAZ",IF(I51="TBD","MPN GEREKLİ","SEÇİLDİ"))) | R51: TBD | S51: TBD
A52: 51 | B52: =IF(C52="",0,LEN(C52)-LEN(SUBSTITUTE(C52,",",""))+1) | C52: R1, R10, R23, R27, R34, R35, R36, R37, R56, R57 | D52: 10k | E52: Resistor | TBD | F52: 0402 (1005 Metric) | G52: Resistor_SMD:R_0402_1005Metric | H52: TBD | I52: TBD | J52: Resistors | K52: Chip Resistor - Surface Mount | L52: Surface Mount | M52: TBD | N52: TBD | P52: MCU, USB_PD_CONTROLLER, USER INTERFACE | Q52: =IF(O52="EVET","DNP",IF(I52="N/A","SATIN ALINMAZ",IF(I52="TBD","MPN GEREKLİ","SEÇİLDİ"))) | R52: TBD | ~ | S52: TBD
A53: 52 | B53: =IF(C53="",0,LEN(C53)-LEN(SUBSTITUTE(C53,",",""))+1) | C53: R59 | D53: 10k | E53: TBD | F53: 0402 (1005 Metric) | G53: Resistor_SMD:R_0402_1005Metric | H53: TBD | I53: TBD | J53: Resistors | K53: Chip Resistor - Surface Mount | L53: Surface Mount | M53: TBD | N53: TBD | P53: USB_PD_CONTROLLER | Q53: =IF(O53="EVET","DNP",IF(I53="N/A","SATIN ALINMAZ",IF(I53="TBD","MPN GEREKLİ","SEÇİLDİ"))) | R53: ~ | S53: TBD
A54: 53 | B54: =IF(C54="",0,LEN(C54)-LEN(SUBSTITUTE(C54,",",""))+1) | C54: R8 | D54: 12k | E54: Resistor | F54: 0402 (1005 Metric) | G54: Resistor_SMD:R_0402_1005Metric | H54: TBD | I54: TBD | J54: Resistors | K54: Chip Resistor - Surface Mount | L54: Surface Mount | M54: TBD | N54: TBD | P54: USB_PD_CONTROLLER | Q54: =IF(O54="EVET","DNP",IF(I54="N/A","SATIN ALINMAZ",IF(I54="TBD","MPN GEREKLİ","SEÇİLDİ"))) | R54: TBD | S54: TBD
A55: 54 | B55: =IF(C55="",0,LEN(C55)-LEN(SUBSTITUTE(C55,",",""))+1) | C55: R41 | D55: 12k7 | E55: TBD | F55: 0402 (1005 Metric) | G55: Resistor_SMD:R_0402_1005Metric | H55: TBD | I55: TBD | J55: Resistors | K55: Chip Resistor - Surface Mount | L55: Surface Mount | M55: TBD | N55: TBD | P55: USB_PD_CONTROLLER | Q55: =IF(O55="EVET","DNP",IF(I55="N/A","SATIN ALINMAZ",IF(I55="TBD","MPN GEREKLİ","SEÇİLDİ"))) | R55: TBD | S55: TBD
A56: 55 | B56: =IF(C56="",0,LEN(C56)-LEN(SUBSTITUTE(C56,",",""))+1) | C56: R22, R51, R54 | D56: 1k0 | E56: Resistor | TBD | F56: 0402 (1005 Metric) | G56: Resistor_SMD:R_0402_1005Metric | H56: TBD | I56: TBD | J56: Resistors | K56: Chip Resistor - Surface Mount | L56: Surface Mount | M56: TBD | N56: TBD | P56: MCU, USB_PD_CONTROLLER | Q56: =IF(O56="EVET","DNP",IF(I56="N/A","SATIN ALINMAZ",IF(I56="TBD","MPN GEREKLİ","SEÇİLDİ"))) | R56: TBD | ~ | S56: TBD
A57: 56 | B57: =IF(C57="",0,LEN(C57)-LEN(SUBSTITUTE(C57,",",""))+1) | C57: R43 | D57: 1k0 | E57: TBD | F57: 2512 (6332 Metric) | G57: Resistor_SMD:R_2512_6332Metric | H57: TBD | I57: TBD | J57: Resistors | K57: Chip Resistor - Surface Mount | L57: Surface Mount | M57: TBD | N57: TBD | P57: USB_PD_CONTROLLER | Q57: =IF(O57="EVET","DNP",IF(I57="N/A","SATIN ALINMAZ",IF(I57="TBD","MPN GEREKLİ","SEÇİLDİ"))) | R57: TBD | S57: Sont besleme: 28V'ta 0.651W. Gercek 2W parca secilecek; ayak 2512.
A58: 57 | B58: =IF(C58="",0,LEN(C58)-LEN(SUBSTITUTE(C58,",",""))+1) | C58: R9 | D58: 20k | E58: Resistor | F58: 0402 (1005 Metric) | G58: Resistor_SMD:R_0402_1005Metric | H58: TBD | I58: TBD | J58: Resistors | K58: Chip Resistor - Surface Mount | L58: Surface Mount | M58: TBD | N58: TBD | P58: USB_PD_CONTROLLER | Q58: =IF(O58="EVET","DNP",IF(I58="N/A","SATIN ALINMAZ",IF(I58="TBD","MPN GEREKLİ","SEÇİLDİ"))) | R58: TBD | S58: TBD
A59: 58 | B59: =IF(C59="",0,LEN(C59)-LEN(SUBSTITUTE(C59,",",""))+1) | C59: R2, R3, R15, R16 | D59: 22R | E59: Resistor | F59: 0402 (1005 Metric) | G59: Resistor_SMD:R_0402_1005Metric | H59: TBD | I59: TBD | J59: Resistors | K59: Chip Resistor - Surface Mount | L59: Surface Mount | M59: TBD | N59: TBD | P59: MCU | Q59: =IF(O59="EVET","DNP",IF(I59="N/A","SATIN ALINMAZ",IF(I59="TBD","MPN GEREKLİ","SEÇİLDİ"))) | R59: TBD | S59: TBD
A60: 59 | B60: =IF(C60="",0,LEN(C60)-LEN(SUBSTITUTE(C60,",",""))+1) | C60: R55 | D60: 232k | E60: TBD | F60: 0402 (1005 Metric) | G60: Resistor_SMD:R_0402_1005Metric | H60: TBD | I60: TBD | J60: Resistors | K60: Chip Resistor - Surface Mount | L60: Surface Mount | M60: TBD | N60: TBD | P60: USB_PD_CONTROLLER | Q60: =IF(O60="EVET","DNP",IF(I60="N/A","SATIN ALINMAZ",IF(I60="TBD","MPN GEREKLİ","SEÇİLDİ"))) | R60: ~ | S60: TBD
... A83: 82 | B83: =IF(C83="",0,LEN(C83)-LEN(SUBSTITUTE(C83,",",""))+1) | C83: TP1, TP2, TP3, TP4, TP5, TP6, TP7, TP8, TP9, TP10, TP11, TP12, TP13 | D83: TestPoint | E83: test point | F83: SMD Pad D1.0mm | G83: TestPoint:TestPoint_Pad_D1.0mm | H83: N/A | I83: N/A | J83: Test and Measurement | K83: Test Points | L83: Surface Mount | M83: N/A | N83: N/A | P83: MCU, USB_PD_CONTROLLER | Q83: =IF(O83="EVET","DNP",IF(I83="N/A","SATIN ALINMAZ",IF(I83="TBD","MPN GEREKLİ","SEÇİLDİ"))) | R83: TBD | ~ | S83: 1.0 mm SMD test pedi; satin alinan parca degildir.
...

Sheet Komponentler
A1: Referans | B1: BOM # | C1: Value | D1: Footprint | E1: Üretici | F1: MPN | G1: Sayfa | H1: DNP | I1: Grup | J1: Kategori | K1: Alt Kategori
A2: U1 | B2: 2 | C2: AP33772SDKZ-13-FA02 | D2: Package_DFN_QFN:Texas_RTW_WQFN-24-1EP_4x4mm_P0.5mm_EP2.7x2.7mm | E2: Diodes Incorporated | F2: AP33772SDKZ-13-FA02 | G2: USB_PD_CONTROLLER | I2: U-PD | J2: Integrated Circuits | K2: Interface - Specialized (USB PD)
A3: U2 | B3: 5 | C3: ESP32-C6-WROOM-1 | D3: PCM_Espressif:ESP32-C6-WROOM-1 | E3: Espressif Systems | F3: ESP32-C6-WROOM-1 | G3: MCU | I3: U-MCU | J3: Integrated Circuits | K3: Embedded - Microcontrollers / RF Modules
A4: U3 | B4: 6 | C4: INA228 | D4: Package_SO:TSSOP-10_3x3mm_P0.5mm | E4: Texas Instruments | F4: INA228AIDGSR | G4: USB_PD_CONTROLLER | I4: U-ANA | J4: Integrated Circuits | K4: Linear - Amplifiers / Data Acquisition
A5: U4 | B5: 7 | C5: RV-3028-C7 | D5: Package_SON:MicroCrystal_C7_SON-8_1.5x3.2mm_P0.9mm | E5: Micro Crystal | F5: RV-3028-C7 | G5: MCU | I5: U-DIG | J5: Integrated Circuits | K5: Logic / Memory / Clock-Timing
A6: U5 | B6: 1 | C6: AOZ1284PI | D6: Package_SO:SOIC-8-1EP_3.9x4.9mm_P1.27mm_EP2.71x3.7mm | E6: Alpha & Omega Semiconductor | F6: AOZ1284PI | G6: USB_PD_CONTROLLER | I6: U-SMPS | J6: Integrated Circuits | K6: PMIC - Voltage Regulators - DC DC Switching
A7: U6 | B7: 8 | C7: TL431BIDBZR | D7: Package_TO_SOT_SMD:SOT-23 | E7: Texas Instruments | F7: TL431BIDBZR | G7: USB_PD_CONTROLLER | I7: U-ANA | J7: Integrated Circuits | K7: Linear - Amplifiers / Data Acquisition
A8: U7 | B8: 11 | C8: TPS61023DRLR | D8: Power_Management_Custom:TPS61023_DRL0006A | E8: Texas Instruments | F8: TPS61023DRLR | G8: USER INTERFACE | I8: U-SMPS | J8: Integrated Circuits | K8: PMIC - Voltage Regulators - DC DC Switching
A9: U8 | B9: 4 | C9: CAT4104V-GT3 | D9: Package_SO:SOIC-8_3.9x4.9mm_P1.27mm | E9: onsemi | F9: CAT4104V-GT3 | G9: USER INTERFACE | J9: Integrated Circuits | K9: PMIC - LED Drivers
A10: U10 | B10: 9 | C10: TPD4EUSB30 | D10: Package_SON:USON-10_2.5x1.0mm_P0.5mm | E10: Texas Instruments | F10: TPD4EUSB30 | G10: USB_C_INPUT | I10: TVS | J10: Circuit Protection | K10: TVS Diodes
A11: U11 | B11: 10 | C11: TPS55340PWPR | D11: Package_SO:Texas_HTSSOP-14-1EP_4.4x5mm_P0.65mm_EP3.4x5mm_Mask3.155x3.255mm_ThermalVias | E11: Texas Instruments | F11: TPS55340PWPR | G11: USB_PD_CONTROLLER | I11: U-SMPS | J11: Integrated Circuits | K11: PMIC - Voltage Regulators - DC DC Switching
A12: U12 | B12: 3 | C12: AP74502Q | D12: Package_TO_SOT_SMD:TSOT-23-8_HandSoldering | E12: Power_Path_Custom | F12: AP74502Q | G12: USB_PD_CONTROLLER | I12: U-SW | J12: Integrated Circuits | K12: PMIC - Power Distribution Switches, Load Drivers
A13: Q1 | B13: 13 | C13: BSS138 | D13: Package_TO_SOT_SMD:SOT-23 | E13: onsemi | F13: BSS138 | G13: USB_PD_CONTROLLER | I13: Q | J13: Discrete Semiconductor Products | K13: FETs, MOSFETs - Single
A14: Q2 | B14: 13 | C14: BSS138 | D14: Package_TO_SOT_SMD:SOT-23 | E14: onsemi | F14: BSS138 | G14: USB_PD_CONTROLLER | I14: Q | J14: Discrete Semiconductor Products | K14: FETs, MOSFETs - Single
A15: Q3 | B15: 14 | C15: IRF7855TRPBF | D15: Package_SO:SOIC-8_3.9x4.9mm_P1.27mm | E15: Infineon Technologies | F15: IRF7855TRPBF | G15: USB_PD_CONTROLLER | I15: Q | J15: Discrete Semiconductor Products | K15: FETs, MOSFETs - Single
A16: Q4 | B16: 14 | C16: IRF7855TRPBF | D16: Package_SO:SOIC-8_3.9x4.9mm_P1.27mm | E16: Infineon Technologies | F16: IRF7855TRPBF | G16: USB_PD_CONTROLLER | I16: Q | J16: Discrete Semiconductor Products | K16: FETs, MOSFETs - Single
A17: Q5 | B17: 12 | C17: 60V 4mR TBD | E17: TBD | F17: TBD | G17: USB_PD_CONTROLLER | I17: Q | J17: Discrete Semiconductor Products | K17: FETs, MOSFETs - Single
A18: Q6 | B18: 12 | C18: 60V 4mR TBD | E18: TBD | F18: TBD | G18: USB_PD_CONTROLLER | I18: Q | J18: Discrete Semiconductor Products | K18: FETs, MOSFETs - Single
A19: D1 | B19: 17 | C19: LED | D19: LED_SMD:LED_0402_1005Metric | E19: TBD | F19: TBD | G19: USB_PD_CONTROLLER | I19: LED | J19: Optoelectronics | K19: LED Indication - Discrete
A20: D2 | B20: 19 | C20: SS2060FL | D20: Diode_SMD:D_SOD-123F | E20: PANJIT | F20: SS2060FL_R1_00001 | G20: USB_PD_CONTROLLER | I20: D | J20: Discrete Semiconductor Products | K20: Diodes
A21: D3 | B21: 18 | C21: SMBJ30A | D21: Diode_SMD:D_SMB | E21: TBD | F21: SMBJ30A | G21: USB_C_INPUT | I21: TVS | J21: Circuit Protection | K21: TVS Diodes
A22: D4 | B22: 20 | C22: SS34 TBD | D22: Diode_SMD:D_SMA | E22: TBD | F22: TBD | G22: USB_PD_CONTROLLER | I22: D | J22: Discrete Semiconductor Products | K22: Diodes
A23: D5 | B23: 15 | C23: BAT54 | D23: Diode_SMD:D_SOD-123 | E23: TBD | F23: BAT54 | G23: USB_PD_CONTROLLER | I23: D | J23: Discrete Semiconductor Products | K23: Diodes
A24: D6 | B24: 16 | C24: BZT52C12 | D24: Diode_SMD:D_SOD-123 | E24: TBD | F24: BZT52C12 | G24: USB_PD_CONTROLLER | I24: D | J24: Discrete Semiconductor Products | K24: Diodes
A25: D7 | B25: 18 | C25: SMBJ30A | D25: Diode_SMD:D_SMB | E25: TBD | F25: SMBJ30A | G25: USB_PD_CONTROLLER | I25: TVS | J25: Circuit Protection | K25: TVS Diodes
A26: L1 | B26: 21 | C26: 22u | D26: Inductor_SMD:L_7.3x7.3_H4.5 | E26: CORE MASTER | F26: SRI0704-220M | G26: USB_PD_CONTROLLER | I26: L | J26: Inductors, Coils, Chokes | K26: Fixed Inductors
A27: L2 | B27: 22 | C27: 2u2 | D27: Inductor_SMD:L_Wuerth_MAPI-4030 | E27: Wurth Elektronik | F27: 74438357022 | G27: USER INTERFACE | I27: L | J27: Inductors, Coils, Chokes | K27: Fixed Inductors
A28: L3 | B28: 23 | C28: 6u8 | D28: Inductor_SMD:L_1210_3225Metric | E28: TBD | F28: TBD | G28: USB_PD_CONTROLLER | I28: L | J28: Inductors, Coils, Chokes | K28: Fixed Inductors
A29: C1 | B29: 25 | C29: 100n | D29: Capacitor_SMD:C_0402_1005Metric | E29: TBD | F29: TBD | G29: USB_PD_CONTROLLER | I29: C | J29: Capacitors | K29: Ceramic Capacitors
A30: C2 | B30: 25 | C30: 100n | D30: Capacitor_SMD:C_0402_1005Metric | E30: TBD | F30: TBD | G30: USB_PD_CONTROLLER | I30: C | J30: Capacitors | K30: Ceramic Capacitors
... A76: R16 | B76: 58 | C76: 22R | D76: Resistor_SMD:R_0402_1005Metric | E76: TBD | F76: TBD | G76: MCU | I76: R | J76: Resistors | K76: Chip Resistor - Surface Mount
A77: R21 | B77: 47 | C77: 100k | D77: Resistor_SMD:R_0402_1005Metric | E77: TBD | F77: TBD | G77: USB_PD_CONTROLLER | H77: EVET | I77: R | J77: Resistors | K77: Chip Resistor - Surface Mount
A78: R22 | B78: 55 | C78: 1k0 | D78: Resistor_SMD:R_0402_1005Metric | E78: TBD | F78: TBD | G78: MCU | I78: R | J78: Resistors | K78: Chip Resistor - Surface Mount
A79: R23 | B79: 51 | C79: 10k | D79: Resistor_SMD:R_0402_1005Metric | E79: TBD | F79: TBD | G79: MCU | I79: R | J79: Resistors | K79: Chip Resistor - Surface Mount
A80: R24 | B80: 65 | C80: 4k7 | D80: Resistor_SMD:R_0402_1005Metric | E80: TBD | F80: TBD | G80: MCU | I80: R | J80: Resistors | K80: Chip Resistor - Surface Mount
A81: R25 | B81: 65 | C81: 4k7 | D81: Resistor_SMD:R_0402_1005Metric | E81: TBD | F81: TBD | G81: MCU | I81: R | J81: Resistors | K81: Chip Resistor - Surface Mount
A82: R26 | B82: 65 | C82: 4k7 | D82: Resistor_SMD:R_0402_1005Metric | E82: TBD | F82: TBD | G82: MCU | I82: R | J82: Resistors | K82: Chip Resistor - Surface Mount
A83: R27 | B83: 51 | C83: 10k | D83: Resistor_SMD:R_0402_1005Metric | E83: TBD | F83: TBD | G83: USB_PD_CONTROLLER | I83: R | J83: Resistors | K83: Chip Resistor - Surface Mount
A84: R28 | B84: 45 | C84: 100R | D84: Resistor_SMD:R_0402_1005Metric | E84: TBD | F84: TBD | G84: USER INTERFACE | I84: R | J84: Resistors | K84: Chip Resistor - Surface Mount
A85: R29 | B85: 48 | C85: 100k | D85: Resistor_SMD:R_0402_1005Metric | E85: TBD | F85: TBD | G85: USER INTERFACE | I85: R | J85: Resistors | K85: Chip Resistor - Surface Mount
...

Sheet Parametreler
A1: BOM # | B1: Referanslar | C1: Value | D1: Grup | E1: Alan | F1: Değer
A2: 1 | B2: U5 | C2: AOZ1284PI | D2: U-SMPS | E2: SupplyVoltage | F2: TBD
A3: 1 | B3: U5 | C3: AOZ1284PI | D3: U-SMPS | E3: PinCount | F3: TBD
A4: 1 | B4: U5 | C4: AOZ1284PI | D4: U-SMPS | E4: ThermalPad | F4: TBD
A5: 1 | B5: U5 | C5: AOZ1284PI | D5: U-SMPS | E5: InterfaceType | F5: None
A6: 1 | B6: U5 | C6: AOZ1284PI | D6: U-SMPS | E6: Topology | F6: Buck
A7: 1 | B7: U5 | C7: AOZ1284PI | D7: U-SMPS | E7: InputVoltage | F7: TBD
A8: 1 | B8: U5 | C8: AOZ1284PI | D8: U-SMPS | E8: OutputVoltage | F8: TBD
A9: 1 | B9: U5 | C9: AOZ1284PI | D9: U-SMPS | E9: OutputCurrent | F9: TBD
A10: 1 | B10: U5 | C10: AOZ1284PI | D10: U-SMPS | E10: SwitchingFrequency | F10: TBD
A11: 1 | B11: U5 | C11: AOZ1284PI | D11: U-SMPS | E11: IntegratedSwitch | F11: TBD
A12: 1 | B12: U5 | C12: AOZ1284PI | D12: U-SMPS | E12: Synchronous | F12: TBD
A13: 1 | B13: U5 | C13: AOZ1284PI | D13: U-SMPS | E13: ControlMode | F13: TBD
... A501: 82 | B501: TP1, TP2, TP3, TP4, TP5, TP6, TP7, TP8, TP9, TP10, TP11, TP12, TP13 | C501: TestPoint | D501: TP | E501: PadDiameter | F501: 1.0mm

Sheet Eksikler
A1: Kapatılacak veri boşlukları
A2: TBD = değer henüz belirlenmedi. Sayılar BOM ve Parametreler sayfalarından formülle çekilir; o sayfalarda TBD yerine gerçek değeri yazınca burası kendiliğinden güncellenir.
A4: Alan | B4: Kaynak | C4: TBD satır | D4: Toplam satır | E4: Doluluk
A5: Üretici | B5: BOM | C5: =COUNTIF(BOM!H2:H83,"TBD") | D5: 82 | E5: =IF(D5=0,0,1-C5/D5)
A6: MPN | B6: BOM | C6: =COUNTIF(BOM!I2:I83,"TBD") | D6: 82 | E6: =IF(D6=0,0,1-C6/D6)
A7: Açıklama | B7: BOM | C7: =COUNTIF(BOM!E2:E83,"TBD") | D7: 82 | E7: =IF(D7=0,0,1-C7/D7)
A8: Package | B8: BOM | C8: =COUNTIF(BOM!F2:F83,"TBD") | D8: 82 | E8: =IF(D8=0,0,1-C8/D8)
A9: Montaj | B9: BOM | C9: =COUNTIF(BOM!L2:L83,"TBD") | D9: 82 | E9: =IF(D9=0,0,1-C9/D9)
A10: Lifecycle | B10: BOM | C10: =COUNTIF(BOM!M2:M83,"TBD") | D10: 82 | E10: =IF(D10=0,0,1-C10/D10)
A11: RoHS | B11: BOM | C11: =COUNTIF(BOM!N2:N83,"TBD") | D11: 82 | E11: =IF(D11=0,0,1-C11/D11)
A12: Datasheet | B12: BOM | C12: =COUNTIF(BOM!R2:R83,"TBD") | D12: 82 | E12: =IF(D12=0,0,1-C12/D12)
A13: Tasarım Notu | B13: BOM | C13: =COUNTIF(BOM!S2:S83,"TBD") | D13: 82 | E13: =IF(D13=0,0,1-C13/D13)
A14: ActuationForce | B14: Parametreler | C14: =COUNTIFS(Parametreler!$E$2:$E$501,A14,Parametreler!$F$2:$F$501,"TBD") | D14: =COUNTIF(Parametreler!$E$2:$E$501,A14) | E14: =IF(D14=0,0,1-C14/D14)
A15: AntennaType | B15: Parametreler | C15: =COUNTIFS(Parametreler!$E$2:$E$501,A15,Parametreler!$F$2:$F$501,"TBD") | D15: =COUNTIF(Parametreler!$E$2:$E$501,A15) | E15: =IF(D15=0,0,1-C15/D15)
A16: BatteryType | B16: Parametreler | C16: =COUNTIFS(Parametreler!$E$2:$E$501,A16,Parametreler!$F$2:$F$501,"TBD") | D16: =COUNTIF(Parametreler!$E$2:$E$501,A16) | E16: =IF(D16=0,0,1-C16/D16)
A17: BreakdownVoltage | B17: Parametreler | C17: =COUNTIFS(Parametreler!$E$2:$E$501,A17,Parametreler!$F$2:$F$501,"TBD") | D17: =COUNTIF(Parametreler!$E$2:$E$501,A17) | E17: =IF(D17=0,0,1-C17/D17)
A18: CCPinsPresent | B18: Parametreler | C18: =COUNTIFS(Parametreler!$E$2:$E$501,A18,Parametreler!$F$2:$F$501,"TBD") | D18: =COUNTIF(Parametreler!$E$2:$E$501,A18) | E18: =IF(D18=0,0,1-C18/D18)
A19: Capacitance | B19: Parametreler | C19: =COUNTIFS(Parametreler!$E$2:$E$501,A19,Parametreler!$F$2:$F$501,"TBD") | D19: =COUNTIF(Parametreler!$E$2:$E$501,A19) | E19: =IF(D19=0,0,1-C19/D19)
A20: Capacity | B20: Parametreler | C20: =COUNTIFS(Parametreler!$E$2:$E$501,A20,Parametreler!$F$2:$F$501,"TBD") | D20: =COUNTIF(Parametreler!$E$2:$E$501,A20) | E20: =IF(D20=0,0,1-C20/D20)
A21: CellSize | B21: Parametreler | C21: =COUNTIFS(Parametreler!$E$2:$E$501,A21,Parametreler!$F$2:$F$501,"TBD") | D21: =COUNTIF(Parametreler!$E$2:$E$501,A21) | E21: =IF(D21=0,0,1-C21/D21)
A22: Certification | B22: Parametreler | C22: =COUNTIFS(Parametreler!$E$2:$E$501,A22,Parametreler!$F$2:$F$501,"TBD") | D22: =COUNTIF(Parametreler!$E$2:$E$501,A22) | E22: =IF(D22=0,0,1-C22/D22)
A23: ChannelCount | B23: Parametreler | C23: =COUNTIFS(Parametreler!$E$2:$E$501,A23,Parametreler!$F$2:$F$501,"TBD") | D23: =COUNTIF(Parametreler!$E$2:$E$501,A23) | E23: =IF(D23=0,0,1-C23/D23)
A24: ChannelType | B24: Parametreler | C24: =COUNTIFS(Parametreler!$E$2:$E$501,A24,Parametreler!$F$2:$F$501,"TBD") | D24: =COUNTIF(Parametreler!$E$2:$E$501,A24) | E24: =IF(D24=0,0,1-C24/D24)
A25: Chemistry | B25: Parametreler | C25: =COUNTIFS(Parametreler!$E$2:$E$501,A25,Parametreler!$F$2:$F$501,"TBD") | D25: =COUNTIF(Parametreler!$E$2:$E$501,A25) | E25: =IF(D25=0,0,1-C25/D25)
... A129: ZenerVoltage | B129: Parametreler | C129: =COUNTIFS(Parametreler!$E$2:$E$501,A129,Parametreler!$F$2:$F$501,"TBD") | D129: =COUNTIF(Parametreler!$E$2:$E$501,A129) | E129: =IF(D129=0,0,1-C129/D129)
